Workbook

Sheet Resumen
A1: PROGRAMA ARQUITECTÓNICO · FIC-UNI · resumen por edificio y nivel
A3: Edificio | B3: Nivel | C3: Cota (m) | D3: Uso principal | E3: Útil (m²) | F3: Circulación (m²) | G3: Libre (m²) | H3: Muros y tolerancia (m²) | I3: Huella (m²) | J3: Aforo | K3: Plazas
A4: Edificio 1 | B4: Sótano 2 | C4: -6 | D4: Estacionamiento, cisterna y bombas | E4: ='Edificio 1'!G11 | F4: ='Edificio 1'!G12 | G4: 0 | H4: ='Edificio 1'!G13 | I4: ='Edificio 1'!G14 | J4: ='Edificio 1'!H11 | K4: 9
A5: Edificio 1 | B5: Sótano 1 | C5: -3 | D5: Estacionamiento, grupo electrógeno y depósito | E5: ='Edificio 1'!G24 | F5: ='Edificio 1'!G25 | G5: 0 | H5: ='Edificio 1'!G26 | I5: ='Edificio 1'!G27 | J5: ='Edificio 1'!H24 | K5: 9
A6: Edificio 1 | B6: Piso 1 | C6: 0 | D6: Hall, sala de estudio y administración | E6: ='Edificio 1'!G38 | F6: ='Edificio 1'!G39 | G6: 0 | H6: ='Edificio 1'!G40 | I6: ='Edificio 1'!G41 | J6: ='Edificio 1'!H38
A7: Edificio 1 | B7: Piso 2 | C7: 3 | D7: Laboratorio 1 y aula de cómputo | E7: ='Edificio 1'!G51 | F7: ='Edificio 1'!G52 | G7: 0 | H7: ='Edificio 1'!G53 | I7: ='Edificio 1'!G54 | J7: ='Edificio 1'!H51
A8: Edificio 1 | B8: Piso 3 | C8: 6 | D8: Laboratorio 2 y aula BIM | E8: ='Edificio 1'!G64 | F8: ='Edificio 1'!G65 | G8: 0 | H8: ='Edificio 1'!G66 | I8: ='Edificio 1'!G67 | J8: ='Edificio 1'!H64
A9: Edificio 1 | B9: Piso 4 | C9: 9 | D9: Laboratorio 3, oficina y depósito de impresoras | E9: ='Edificio 1'!G78 | F9: ='Edificio 1'!G79 | G9: 0 | H9: ='Edificio 1'!G80 | I9: ='Edificio 1'!G81 | J9: ='Edificio 1'!H78
A10: Edificio 1 | B10: Piso 5 | C10: 12 | D10: Aula taller con oficina y depósito | E10: ='Edificio 1'!G92 | F10: ='Edificio 1'!G93 | G10: 0 | H10: ='Edificio 1'!G94 | I10: ='Edificio 1'!G95 | J10: ='Edificio 1'!H92
A11: Edificio 1 | B11: Piso 6 | C11: 15 | D11: 3 aulas teóricas y sala de reuniones | E11: ='Edificio 1'!G104 | F11: ='Edificio 1'!G105 | G11: 0 | H11: ='Edificio 1'!G106 | I11: ='Edificio 1'!G107 | J11: ='Edificio 1'!H104
A12: Edificio 1 | B12: Piso 7 | C12: 18 | D12: Aula magna de 60 personas, foyer y terraza | E12: ='Edificio 1'!G119 | F12: ='Edificio 1'!G120 | G12: ='Edificio 1'!G121 | H12: ='Edificio 1'!G122 | I12: ='Edificio 1'!G123 | J12: ='Edificio 1'!H119
A13: Edificio 1 | B13: Azotea técnica | C13: 21 | D13: Tanque elevado y equipos de extracción | E13: ='Edificio 1'!G129 | F13: ='Edificio 1'!G130 | G13: ='Edificio 1'!G131 | H13: ='Edificio 1'!G132 | I13: ='Edificio 1'!G133 | J13: ='Edificio 1'!H129
A14: EDIFICIO 1 | B14: TOTAL (sin azotea) | E14: =SUM(E4:E12) | F14: =SUM(F4:F12) | G14: =SUM(G4:G12) | H14: =SUM(H4:H12) | I14: =SUM(I4:I12) | J14: =SUM(J4:J12) | K14: =SUM(K4:K12)
A15: Edificio 2 | B15: Sótano 1 | C15: -3 | D15: Piso de servidumbre: depósito y equipos | E15: ='Edificio 2'!G12 | F15: ='Edificio 2'!G13 | G15: 0 | H15: ='Edificio 2'!G14 | I15: ='Edificio 2'!G15 | J15: ='Edificio 2'!H12
A16: Edificio 2 | B16: Piso 1 | C16: 0 | D16: Cafetería y hall de acceso | E16: ='Edificio 2'!G26 | F16: ='Edificio 2'!G27 | G16: 0 | H16: ='Edificio 2'!G28 | I16: ='Edificio 2'!G29 | J16: ='Edificio 2'!H26
A17: Edificio 2 | B17: Piso 2 | C17: 3 | D17: Aula de idiomas 1 y sala de práctica | E17: ='Edificio 2'!G39 | F17: ='Edificio 2'!G40 | G17: 0 | H17: ='Edificio 2'!G41 | I17: ='Edificio 2'!G42 | J17: ='Edificio 2'!H39
A18: Edificio 2 | B18: Piso 3 | C18: 6 | D18: Aula de idiomas 2 y sala de práctica | E18: ='Edificio 2'!G52 | F18: ='Edificio 2'!G53 | G18: 0 | H18: ='Edificio 2'!G54 | I18: ='Edificio 2'!G55 | J18: ='Edificio 2'!H52
A19: Edificio 2 | B19: Piso 4 | C19: 9 | D19: Aula de idiomas 3 y sala de práctica | E19: ='Edificio 2'!G65 | F19: ='Edificio 2'!G66 | G19: 0 | H19: ='Edificio 2'!G67 | I19: ='Edificio 2'!G68 | J19: ='Edificio 2'!H65
A20: EDIFICIO 2 | B20: TOTAL | E20: =SUM(E15:E19) | F20: =SUM(F15:F19) | G20: =SUM(G15:G19) | H20: =SUM(H15:H19) | I20: =SUM(I15:I19) | J20: =SUM(J15:J19) | K20: =SUM(K15:K19)
A21: CONJUNTO | B21: E1 + E2 | E21: =E14+E20 | F21: =F14+F20 | G21: =G14+G20 | H21: =H14+H20 | I21: =I14+I20 | J21: =J14+J20 | K21: =K14+K20

Sheet Edificio 1
A1: EDIFICIO 1 · huella 26.16 × 15.42 m = 403.4 m² · 9 niveles + azotea técnica
A3: Nivel | B3: Cota (m) | C3: Ambiente | D3: Categoría | E3: Cant. | F3: Área unit. (m²) | G3: Área total (m²) | H3: Aforo | I3: Ventilación | J3: Observaciones
A4: SÓTANO 2 · Estacionamiento, cisterna y bombas | B4: -6
A5: Sótano 2 | B5: -6 | C5: Estacionamiento (9 plazas) | D5: Estacionamiento y rampa | E5: 1 | F5: 222.3 | G5: =E5*F5
A6: Sótano 2 | B6: -6 | C6: Rampa vehicular (tramo interior) | D6: Estacionamiento y rampa | E6: 1 | F6: 55 | G6: =E6*F6 | J6: El tramo exterior se desarrolla en el área libre (pendiente ≤ 15 %)
A7: Sótano 2 | B7: -6 | C7: Cisterna y cuarto de bombas | D7: Servidumbre (equipos) | E7: 1 | F7: 60 | G7: =E7*F7 | J7: Piso de servidumbre
A8: Sótano 2 | B8: -6 | C8: Escalera de evacuación protegida | D8: Escalera y ascensor | E8: 2 | F8: 16 | G8: =E8*F8 | J8: Protegida, ancho libre ≥ 1.20 m
A9: Sótano 2 | B9: -6 | C9: Ductos de instalaciones y ventilación | D9: SS.HH. y ductos | E9: 1 | F9: 8 | G9: =E9*F9 | J9: Incluye ducto de extracción
A10: Sótano 2 | B10: -6 | C10: Ascensor accesible (cabina camilla) | D10: Escalera y ascensor | E10: 1 | F10: 7 | G10: =E10*F10 | J10: Acceso universal (RNE A.120)
A11: Sótano 2 | B11: -6 | C11: Subtotal área útil (techada) | G11: =SUM(G5:G10) | H11: =SUM(H5:H10)
A12: Sótano 2 | B12: -6 | C12: Circulación horizontal y hall (corredores, galería, vestíbulos) | D12: Circulación y hall | G12: 19.1 | J12: Sale de la planta dibujada
A13: Sótano 2 | B13: -6 | C13: Muros, columnas y tolerancia | D13: Muros y tolerancia | G13: =MAX(0,ROUND(G14-G11-G12,1)) | J13: Las áreas se miden a ejes de muros
A14: Sótano 2 | B14: -6 | C14: ÁREA BRUTA DEL NIVEL (huella) | G14: 403.4
A16: SÓTANO 1 · Estacionamiento, grupo electrógeno y depósito | B16: -3
A17: Sótano 1 | B17: -3 | C17: Estacionamiento (9 plazas) | D17: Estacionamiento y rampa | E17: 1 | F17: 222.3 | G17: =E17*F17
A18: Sótano 1 | B18: -3 | C18: Rampa vehicular (tramo interior) | D18: Estacionamiento y rampa | E18: 1 | F18: 55 | G18: =E18*F18 | J18: El tramo exterior se desarrolla en el área libre (pendiente ≤ 15 %)
A19: Sótano 1 | B19: -3 | C19: Grupo electrógeno y tableros | D19: Servidumbre (equipos) | E19: 1 | F19: 35 | G19: =E19*F19 | J19: Piso de servidumbre
A20: Sótano 1 | B20: -3 | C20: Depósito general | D20: Depósitos | E20: 1 | F20: 25 | G20: =E20*F20
A21: Sótano 1 | B21: -3 | C21: Escalera de evacuación protegida | D21: Escalera y ascensor | E21: 2 | F21: 16 | G21: =E21*F21 | J21: Protegida, ancho libre ≥ 1.20 m
A22: Sótano 1 | B22: -3 | C22: Ductos de instalaciones y ventilación | D22: SS.HH. y ductos | E22: 1 | F22: 8 | G22: =E22*F22 | J22: Incluye ducto de extracción
A23: Sótano 1 | B23: -3 | C23: Ascensor accesible (cabina camilla) | D23: Escalera y ascensor | E23: 1 | F23: 7 | G23: =E23*F23 | J23: Acceso universal (RNE A.120)
A24: Sótano 1 | B24: -3 | C24: Subtotal área útil (techada) | G24: =SUM(G17:G23) | H24: =SUM(H17:H23)
A25: Sótano 1 | B25: -3 | C25: Circulación horizontal y hall (corredores, galería, vestíbulos) | D25: Circulación y hall | G25: 19.1 | J25: Sale de la planta dibujada
A26: Sótano 1 | B26: -3 | C26: Muros, columnas y tolerancia | D26: Muros y tolerancia | G26: =MAX(0,ROUND(G27-G24-G25,1)) | J26: Las áreas se miden a ejes de muros
A27: Sótano 1 | B27: -3 | C27: ÁREA BRUTA DEL NIVEL (huella) | G27: 403.4
A29: PISO 1 · Hall, sala de estudio y administración | B29: 0
A30: Piso 1 | B30: 0 | C30: Sala de estudio | D30: Sala de estudio | E30: 1 | F30: 120 | G30: =E30*F30 | H30: 60 | I30: Natural | J30: 2 m²/persona
A31: Piso 1 | B31: 0 | C31: Oficina de coordinación | D31: Administración y docentes | E31: 1 | F31: 30 | G31: =E31*F31 | H31: 4
A32: Piso 1 | B32: 0 | C32: Recepción y control | D32: Administración y docentes | E32: 1 | F32: 15 | G32: =E32*F32 | H32: 2
A33: Piso 1 | B33: 0 | C33: Escalera de evacuación protegida | D33: Escalera y ascensor | E33: 2 | F33: 16 | G33: =E33*F33 | J33: Protegida, ancho libre ≥ 1.20 m
A34: Piso 1 | B34: 0 | C34: Ductos de instalaciones y ventilación | D34: SS.HH. y ductos | E34: 1 | F34: 6 | G34: =E34*F34 | J34: Incluye ducto de extracción
A35: Piso 1 | B35: 0 | C35: Ascensor accesible (cabina camilla) | D35: Escalera y ascensor | E35: 1 | F35: 7 | G35: =E35*F35 | J35: Acceso universal (RNE A.120)
A36: Piso 1 | B36: 0 | C36: SS.HH. hombres / mujeres / accesible | D36: SS.HH. y ductos | E36: 1 | F36: 20 | G36: =E36*F36 | J36: Según aforo del nivel
A37: Piso 1 | B37: 0 | C37: Hall de ingreso y distribución | D37: Circulación y hall | E37: 1 | F37: 88 | G37: =E37*F37 | J37: Ingreso principal
A38: Piso 1 | B38: 0 | C38: Subtotal área útil (techada) | G38: =SUM(G30:G37) | H38: =SUM(H30:H37)
A39: Piso 1 | B39: 0 | C39: Circulación horizontal y hall (corredores, galería, vestíbulos) | D39: Circulación y hall | G39: 84.9 | J39: Sale de la planta dibujada
A40: Piso 1 | B40: 0 | C40: Muros, columnas y tolerancia | D40: Muros y tolerancia | G40: =MAX(0,ROUND(G41-G38-G39,1)) | J40: Las áreas se miden a ejes de muros
A41: Piso 1 | B41: 0 | C41: ÁREA BRUTA DEL NIVEL (huella) | G41: 403.4
A43: PISO 2 · Laboratorio 1 y aula de cómputo | B43: 3
A44: Piso 2 | B44: 3 | C44: Laboratorio (40 al.) | D44: Laboratorios | E44: 1 | F44: 200 | G44: =E44*F44 | H44: 40 | I44: Natural + extracción mecánica | J44: 5 m²/alumno; ventilación natural + extracción
...

Sheet Edificio 2
A1: EDIFICIO 2 · huella 18.94 × 9.90 m = 187.5 m² · 5 niveles
A3: Nivel | B3: Cota (m) | C3: Ambiente | D3: Categoría | E3: Cant. | F3: Área unit. (m²) | G3: Área total (m²) | H3: Aforo | I3: Ventilación | J3: Observaciones
A4: SÓTANO 1 · Piso de servidumbre: depósito y equipos | B4: -3
A5: Sótano 1 | B5: -3 | C5: Cuarto de residuos y limpieza | D5: Servidumbre (equipos) | E5: 1 | F5: 16 | G5: =E5*F5
A6: Sótano 1 | B6: -3 | C6: Cuarto de comunicaciones | D6: Servidumbre (equipos) | E6: 1 | F6: 14 | G6: =E6*F6
A7: Sótano 1 | B7: -3 | C7: Depósito general | D7: Depósitos | E7: 1 | F7: 70 | G7: =E7*F7 | J7: Mobiliario, equipos y repuestos
A8: Sótano 1 | B8: -3 | C8: Cuarto de bombas y tablero general | D8: Servidumbre (equipos) | E8: 1 | F8: 30 | G8: =E8*F8 | J8: Piso de servidumbre
A9: Sótano 1 | B9: -3 | C9: Ductos de instalaciones y ventilación | D9: SS.HH. y ductos | E9: 1 | F9: 4 | G9: =E9*F9
A10: Sótano 1 | B10: -3 | C10: Ascensor accesible (cabina camilla) | D10: Escalera y ascensor | E10: 1 | F10: 6 | G10: =E10*F10 | J10: Acceso universal (RNE A.120)
A11: Sótano 1 | B11: -3 | C11: Escalera de evacuación protegida | D11: Escalera y ascensor | E11: 1 | F11: 16 | G11: =E11*F11 | J11: Protegida, ancho libre ≥ 1.20 m
A12: Sótano 1 | B12: -3 | C12: Subtotal área útil (techada) | G12: =SUM(G5:G11) | H12: =SUM(H5:H11)
A13: Sótano 1 | B13: -3 | C13: Circulación horizontal y hall (corredores, galería, vestíbulos) | D13: Circulación y hall | G13: 28.4 | J13: Sale de la planta dibujada
A14: Sótano 1 | B14: -3 | C14: Muros, columnas y tolerancia | D14: Muros y tolerancia | G14: =MAX(0,ROUND(G15-G12-G13,1)) | J14: Las áreas se miden a ejes de muros
A15: Sótano 1 | B15: -3 | C15: ÁREA BRUTA DEL NIVEL (huella) | G15: 187.5
A17: PISO 1 · Cafetería y hall de acceso | B17: 0
A18: Piso 1 | B18: 0 | C18: Cafetería | D18: Cafetería | E18: 1 | F18: 70 | G18: =E18*F18 | H18: 45 | I18: Natural | J18: 1.5 m²/persona
A19: Piso 1 | B19: 0 | C19: Cocina | D19: Cafetería | E19: 1 | F19: 20 | G19: =E19*F19 | H19: 3
A20: Piso 1 | B20: 0 | C20: Almacén y despensa | D20: Depósitos | E20: 1 | F20: 14 | G20: =E20*F20
A21: Piso 1 | B21: 0 | C21: SS.HH. hombres / mujeres / accesible | D21: SS.HH. y ductos | E21: 1 | F21: 14 | G21: =E21*F21 | J21: Según aforo del nivel
A22: Piso 1 | B22: 0 | C22: Ductos de instalaciones y ventilación | D22: SS.HH. y ductos | E22: 1 | F22: 4 | G22: =E22*F22
A23: Piso 1 | B23: 0 | C23: Ascensor accesible (cabina camilla) | D23: Escalera y ascensor | E23: 1 | F23: 6 | G23: =E23*F23 | J23: Acceso universal (RNE A.120)
A24: Piso 1 | B24: 0 | C24: Escalera de evacuación protegida | D24: Escalera y ascensor | E24: 1 | F24: 16 | G24: =E24*F24 | J24: Protegida, ancho libre ≥ 1.20 m
A25: Piso 1 | B25: 0 | C25: Hall de acceso y ascensor | D25: Circulación y hall | E25: 1 | F25: 30 | G25: =E25*F25 | J25: Conexión con el Edificio 1
A26: Piso 1 | B26: 0 | C26: Subtotal área útil (techada) | G26: =SUM(G18:G25) | H26: =SUM(H18:H25)
A27: Piso 1 | B27: 0 | C27: Circulación horizontal y hall (corredores, galería, vestíbulos) | D27: Circulación y hall | G27: 10.3 | J27: Sale de la planta dibujada
A28: Piso 1 | B28: 0 | C28: Muros, columnas y tolerancia | D28: Muros y tolerancia | G28: =MAX(0,ROUND(G29-G26-G27,1)) | J28: Las áreas se miden a ejes de muros
A29: Piso 1 | B29: 0 | C29: ÁREA BRUTA DEL NIVEL (huella) | G29: 187.5
A31: PISO 2 · Aula de idiomas 1 y sala de práctica | B31: 3
A32: Piso 2 | B32: 3 | C32: Aula de idiomas (30 al.) | D32: Aulas | E32: 1 | F32: 50 | G32: =E32*F32 | H32: 30 | I32: Natural | J32: 1.5 m²/alumno
A33: Piso 2 | B33: 3 | C33: Sala de práctica de conversación | D33: Aulas | E33: 1 | F33: 30 | G33: =E33*F33 | H33: 15
A34: Piso 2 | B34: 3 | C34: Depósito | D34: Depósitos | E34: 1 | F34: 10 | G34: =E34*F34
A35: Piso 2 | B35: 3 | C35: SS.HH. hombres / mujeres / accesible | D35: SS.HH. y ductos | E35: 1 | F35: 14 | G35: =E35*F35 | J35: Según aforo del nivel
A36: Piso 2 | B36: 3 | C36: Ductos de instalaciones y ventilación | D36: SS.HH. y ductos | E36: 1 | F36: 4 | G36: =E36*F36
A37: Piso 2 | B37: 3 | C37: Ascensor accesible (cabina camilla) | D37: Escalera y ascensor | E37: 1 | F37: 6 | G37: =E37*F37 | J37: Acceso universal (RNE A.120)
A38: Piso 2 | B38: 3 | C38: Escalera de evacuación protegida | D38: Escalera y ascensor | E38: 1 | F38: 16 | G38: =E38*F38 | J38: Protegida, ancho libre ≥ 1.20 m
A39: Piso 2 | B39: 3 | C39: Subtotal área útil (techada) | G39: =SUM(G32:G38) | H39: =SUM(H32:H38)
A40: Piso 2 | B40: 3 | C40: Circulación horizontal y hall (corredores, galería, vestíbulos) | D40: Circulación y hall | G40: 56.6 | J40: Sale de la planta dibujada
A41: Piso 2 | B41: 3 | C41: Muros, columnas y tolerancia | D41: Muros y tolerancia | G41: =MAX(0,ROUND(G42-G39-G40,1)) | J41: Las áreas se miden a ejes de muros
A42: Piso 2 | B42: 3 | C42: ÁREA BRUTA DEL NIVEL (huella) | G42: 187.5
A44: PISO 3 · Aula de idiomas 2 y sala de práctica | B44: 6
...

Sheet Programa mínimo
A1: PROGRAMA MÍNIMO SOLICITADO · dónde se resuelve
A3: Requisito | B3: Estado | C3: Cómo se resuelve | D3: Niveles
A4: 3 aulas teóricas | B4: Incluido | C4: 3 aulas de 60 m² para 40 alumnos | D4: E1 · Piso 6
A5: 3 aulas de laboratorio de 40 | B5: Incluido | C5: 3 laboratorios de 200 m² (5 m² por alumno), con ventilación natural y extracción | D5: E1 · Piso 2, E1 · Piso 3, E1 · Piso 4
A6: 3 aulas de idiomas | B6: Incluido | C6: Una por piso, con sala de práctica y depósito | D6: E2 · Piso 2, E2 · Piso 3, E2 · Piso 4
A7: 1 aula taller de 40 | B7: Incluido | C7: Con 5 mesas de 1.2 × 1.5 × 1.8 m, ecran, oficina al lado y depósito | D7: E1 · Piso 5
A8: 1 aula BIM y aula de cómputo | B8: Incluido | C8: Aula de cómputo en el piso 2 y aula BIM en el piso 3, cerca de los laboratorios | D8: E1 · Piso 2, E1 · Piso 3
A9: Vestidor y 1 ducha por cada 60 | B9: Incluido | C9: Un vestidor con 2 duchas junto a cada laboratorio | D9: E1 · Piso 2, E1 · Piso 3, E1 · Piso 4
A10: Pisos de servidumbre | B10: Incluido | C10: Sótanos y azotea del Edificio 1, y sótano del Edificio 2 | D10: E1 · Sótano 2, E1 · Sótano 1, E1 · Azotea técnica, E2 · Sótano 1
A11: 1.er piso: cafetería, sala de estudio y hall | B11: Incluido | C11: Cafetería en el Edificio 2; sala de estudio y hall en el Edificio 1 | D11: E2 · Piso 1, E1 · Piso 1
A12: 2 sótanos con estacionamiento | B12: Incluido | C12: 2 sótanos en el Edificio 1 con 18 plazas. Se pueden ampliar bajo el área libre | D12: E1 · Sótano 2, E1 · Sótano 1
A13: Impresoras 2D y 3D en los depósitos | B13: Incluido | C13: En el depósito del piso 4 y en el depósito del taller | D13: E1 · Piso 4, E1 · Piso 5
A14: Aula magna en el último nivel, 60 personas | B14: Incluido | C14: Piso 7 del Edificio 1, con foyer, escenario y terraza | D14: E1 · Piso 7
A15: Ventilación en aulas magnas y laboratorios | B15: Incluido | C15: Ventanas en fachada más extracción mecánica por el ducto del núcleo | D15: E1 · Piso 2, E1 · Piso 3, E1 · Piso 4, E1 · Piso 7
A16: Verificar con coordenadas UTM | B16: Pendiente | C16: Pendiente: faltan las coordenadas reales del lote (ver notas)

Sheet Supuestos
A1: SUPUESTOS Y CAMBIOS
A3: Geometría
A4: Las huellas salen de las capturas del modelo: Edificio 1 de 403.4 m² y Edificio 2 de 187.5 m². Medidas usadas: 26.16 × 15.42 m y 18.94 × 9.90 m (proporción rectangular de esas plantas).
A5: Cada nivel está dibujado en el archivo HTML «distribucion_por_niveles_FIC_UNI.html»; este Excel tiene las mismas áreas.
A6: Las áreas se miden a ejes de muros: el espesor de los muros interiores queda dentro de cada ambiente.
A7: El núcleo (2 escaleras en el Edificio 1, 1 en el Edificio 2, ascensor, SS.HH. y ductos) está en la misma posición en todos los niveles.
A9: Criterios
A10: Aula 1.5 m² por alumno; laboratorio y taller 5 m² por alumno (RNE A.040, confirmar versión vigente). Cómputo y BIM 2 m² por PC.
A11: Ducha: 1 por cada 60 alumnos; se dibujan 2 por vestidor (una por lado).
A12: Mesas del taller (1.2 × 1.5 × 1.8 m): dimensiones en planta por confirmar; se dibujan de 1.8 × 1.5 m.
A13: Laboratorios y aula magna: ventanas en fachada más extracción mecánica por el ducto del núcleo.
A14: Coordenadas UTM zona 18S (WGS84), referenciales del campus: E 276,977 / N 8,670,117. Faltan las coordenadas reales del lote y la orientación al norte.
... A26: Edificio 2, piso 1: cafetería de 70 m², cocina de 20 m² y almacén de 14 m²; hall de acceso y ascensor de 30 m² (antes 20 + 10).
